Workbook

Sheet Overview
A2: E-commerce Funnel Performance
A3: Synthetic demonstration | 1,000 sessions | 2026-07-01 to 2026-09-28 UTC
A5: Product view sessions | C5: Purchase sessions | E5: View-to-purchase | G5: Purchase revenue (USD)
A6: =Funnel!B6 -> 1000 | C6: =Funnel!B9 -> 183 | E6: =Funnel!F9 -> 0.183 | G6: =Funnel!G9 -> 20982.96
A9: Funnel step | B9: Sessions
A10: Product view | B10: =Funnel!B6 -> 1000
A11: Add to cart | B11: =Funnel!B7 -> 443
A12: Begin checkout | B12: =Funnel!B8 -> 263
A13: Purchase | B13: =Funnel!B9 -> 183
A16: How to use this view | B16: Largest session loss first; compare rate and volume by segment.
A17: Data note | B17: Synthetic demo data.
A18: Definitions | B18: Ordered same-session events; see README.

Sheet Funnel
A2: Session Funnel
A3: Reporting window: 2026-07-01 to 2026-09-28 | UTC | Ordered events within the same session
A5: Funnel step | B5: Sessions | C5: Prior step sessions | D5: Step conversion | E5: Step drop-off | F5: Conversion from view | G5: Purchase revenue (USD)
A6: Product view | B6: =SUMIFS('SQL Export'!$G$2:$G$93,'SQL Export'!$C$2:$C$93,"Overall",'SQL Export'!$E$2:$E$93,1) -> 1000 | C6: ="" | D6: ="" | E6: ="" | F6: =IFERROR(B6/$B$6,0) -> 1 | G6: =0 -> 0
A7: Add to cart | B7: =SUMIFS('SQL Export'!$G$2:$G$93,'SQL Export'!$C$2:$C$93,"Overall",'SQL Export'!$E$2:$E$93,2) -> 443 | C7: =B6 -> 1000 | D7: =IFERROR(B7/C7,0) -> 0.443 | E7: =1-D7 -> 0.557 | F7: =IFERROR(B7/$B$6,0) -> 0.443 | G7: =0 -> 0
A8: Begin checkout | B8: =SUMIFS('SQL Export'!$G$2:$G$93,'SQL Export'!$C$2:$C$93,"Overall",'SQL Export'!$E$2:$E$93,3) -> 263 | C8: =B7 -> 443 | D8: =IFERROR(B8/C8,0) -> 0.59367946 | E8: =1-D8 -> 0.40632054 | F8: =IFERROR(B8/$B$6,0) -> 0.263 | G8: =0 -> 0
A9: Purchase | B9: =SUMIFS('SQL Export'!$G$2:$G$93,'SQL Export'!$C$2:$C$93,"Overall",'SQL Export'!$E$2:$E$93,4) -> 183 | C9: =B8 -> 263 | D9: =IFERROR(B9/C9,0) -> 0.69581749 | E9: =1-D9 -> 0.30418251 | F9: =IFERROR(B9/$B$6,0) -> 0.183 | G9: =SUMIFS('SQL Export'!$M$2:$M$93,'SQL Export'!$C$2:$C$93,"Overall",'SQL Export'!$E$2:$E$93,4) -> 20982.96
A12: Metric note | B12: Definition
A13: Step conversion | B13: Current-step sessions ÷ prior-step sessions
A14: Drop-off | B14: 1 − step conversion

Sheet Segments
A2: Segment Performance
A3: Compare funnel rates with session volume before prioritizing an investigation.
A4: Segment type | B4: Segment | C4: Product view sessions | D4: Add-to-cart sessions | E4: Checkout sessions | F4: Purchase sessions | G4: View-to-purchase | H4: Purchase revenue (USD)
A5: Device | B5: desktop | C5: =SUMIFS('SQL Export'!$G$2:$G$93,'SQL Export'!$C$2:$C$93,$A5,'SQL Export'!$D$2:$D$93,$B5,'SQL Export'!$E$2:$E$93,1) -> 294 | D5: =SUMIFS('SQL Export'!$G$2:$G$93,'SQL Export'!$C$2:$C$93,$A5,'SQL Export'!$D$2:$D$93,$B5,'SQL Export'!$E$2:$E$93,2) -> 145 | E5: =SUMIFS('SQL Export'!$G$2:$G$93,'SQL Export'!$C$2:$C$93,$A5,'SQL Export'!$D$2:$D$93,$B5,'SQL Export'!$E$2:$E$93,3) -> 99 | F5: =SUMIFS('SQL Export'!$G$2:$G$93,'SQL Export'!$C$2:$C$93,$A5,'SQL Export'!$D$2:$D$93,$B5,'SQL Export'!$E$2:$E$93,4) -> 77 | G5: =IFERROR(F5/C5,0) -> 0.26190476 | H5: =SUMIFS('SQL Export'!$M$2:$M$93,'SQL Export'!$C$2:$C$93,$A5,'SQL Export'!$D$2:$D$93,$B5,'SQL Export'!$E$2:$E$93,4) -> 9114.17
A6: Device | B6: mobile | C6: =SUMIFS('SQL Export'!$G$2:$G$93,'SQL Export'!$C$2:$C$93,$A6,'SQL Export'!$D$2:$D$93,$B6,'SQL Export'!$E$2:$E$93,1) -> 650 | D6: =SUMIFS('SQL Export'!$G$2:$G$93,'SQL Export'!$C$2:$C$93,$A6,'SQL Export'!$D$2:$D$93,$B6,'SQL Export'!$E$2:$E$93,2) -> 272 | E6: =SUMIFS('SQL Export'!$G$2:$G$93,'SQL Export'!$C$2:$C$93,$A6,'SQL Export'!$D$2:$D$93,$B6,'SQL Export'!$E$2:$E$93,3) -> 147 | F6: =SUMIFS('SQL Export'!$G$2:$G$93,'SQL Export'!$C$2:$C$93,$A6,'SQL Export'!$D$2:$D$93,$B6,'SQL Export'!$E$2:$E$93,4) -> 95 | G6: =IFERROR(F6/C6,0) -> 0.14615385 | H6: =SUMIFS('SQL Export'!$M$2:$M$93,'SQL Export'!$C$2:$C$93,$A6,'SQL Export'!$D$2:$D$93,$B6,'SQL Export'!$E$2:$E$93,4) -> 10793.08
A7: Device | B7: tablet | C7: =SUMIFS('SQL Export'!$G$2:$G$93,'SQL Export'!$C$2:$C$93,$A7,'SQL Export'!$D$2:$D$93,$B7,'SQL Export'!$E$2:$E$93,1) -> 56 | D7: =SUMIFS('SQL Export'!$G$2:$G$93,'SQL Export'!$C$2:$C$93,$A7,'SQL Export'!$D$2:$D$93,$B7,'SQL Export'!$E$2:$E$93,2) -> 26 | E7: =SUMIFS('SQL Export'!$G$2:$G$93,'SQL Export'!$C$2:$C$93,$A7,'SQL Export'!$D$2:$D$93,$B7,'SQL Export'!$E$2:$E$93,3) -> 17 | F7: =SUMIFS('SQL Export'!$G$2:$G$93,'SQL Export'!$C$2:$C$93,$A7,'SQL Export'!$D$2:$D$93,$B7,'SQL Export'!$E$2:$E$93,4) -> 11 | G7: =IFERROR(F7/C7,0) -> 0.19642857 | H7: =SUMIFS('SQL Export'!$M$2:$M$93,'SQL Export'!$C$2:$C$93,$A7,'SQL Export'!$D$2:$D$93,$B7,'SQL Export'!$E$2:$E$93,4) -> 1075.71
A8: Channel | B8: direct / (none) | C8: =SUMIFS('SQL Export'!$G$2:$G$93,'SQL Export'!$C$2:$C$93,$A8,'SQL Export'!$D$2:$D$93,$B8,'SQL Export'!$E$2:$E$93,1) -> 79 | D8: =SUMIFS('SQL Export'!$G$2:$G$93,'SQL Export'!$C$2:$C$93,$A8,'SQL Export'!$D$2:$D$93,$B8,'SQL Export'!$E$2:$E$93,2) -> 35 | E8: =SUMIFS('SQL Export'!$G$2:$G$93,'SQL Export'!$C$2:$C$93,$A8,'SQL Export'!$D$2:$D$93,$B8,'SQL Export'!$E$2:$E$93,3) -> 19 | F8: =SUMIFS('SQL Export'!$G$2:$G$93,'SQL Export'!$C$2:$C$93,$A8,'SQL Export'!$D$2:$D$93,$B8,'SQL Export'!$E$2:$E$93,4) -> 16 | G8: =IFERROR(F8/C8,0) -> 0.20253165 | H8: =SUMIFS('SQL Export'!$M$2:$M$93,'SQL Export'!$C$2:$C$93,$A8,'SQL Export'!$D$2:$D$93,$B8,'SQL Export'!$E$2:$E$93,4) -> 1802.04
A9: Channel | B9: google / cpc | C9: =SUMIFS('SQL Export'!$G$2:$G$93,'SQL Export'!$C$2:$C$93,$A9,'SQL Export'!$D$2:$D$93,$B9,'SQL Export'!$E$2:$E$93,1) -> 239 | D9: =SUMIFS('SQL Export'!$G$2:$G$93,'SQL Export'!$C$2:$C$93,$A9,'SQL Export'!$D$2:$D$93,$B9,'SQL Export'!$E$2:$E$93,2) -> 100 | E9: =SUMIFS('SQL Export'!$G$2:$G$93,'SQL Export'!$C$2:$C$93,$A9,'SQL Export'!$D$2:$D$93,$B9,'SQL Export'!$E$2:$E$93,3) -> 50 | F9: =SUMIFS('SQL Export'!$G$2:$G$93,'SQL Export'!$C$2:$C$93,$A9,'SQL Export'!$D$2:$D$93,$B9,'SQL Export'!$E$2:$E$93,4) -> 33 | G9: =IFERROR(F9/C9,0) -> 0.13807531 | H9: =SUMIFS('SQL Export'!$M$2:$M$93,'SQL Export'!$C$2:$C$93,$A9,'SQL Export'!$D$2:$D$93,$B9,'SQL Export'!$E$2:$E$93,4) -> 3592.29
A10: Channel | B10: google / organic | C10: =SUMIFS('SQL Export'!$G$2:$G$93,'SQL Export'!$C$2:$C$93,$A10,'SQL Export'!$D$2:$D$93,$B10,'SQL Export'!$E$2:$E$93,1) -> 348 | D10: =SUMIFS('SQL Export'!$G$2:$G$93,'SQL Export'!$C$2:$C$93,$A10,'SQL Export'!$D$2:$D$93,$B10,'SQL Export'!$E$2:$E$93,2) -> 164 | E10: =SUMIFS('SQL Export'!$G$2:$G$93,'SQL Export'!$C$2:$C$93,$A10,'SQL Export'!$D$2:$D$93,$B10,'SQL Export'!$E$2:$E$93,3) -> 100 | F10: =SUMIFS('SQL Export'!$G$2:$G$93,'SQL Export'!$C$2:$C$93,$A10,'SQL Export'!$D$2:$D$93,$B10,'SQL Export'!$E$2:$E$93,4) -> 69 | G10: =IFERROR(F10/C10,0) -> 0.19827586 | H10: =SUMIFS('SQL Export'!$M$2:$M$93,'SQL Export'!$C$2:$C$93,$A10,'SQL Export'!$D$2:$D$93,$B10,'SQL Export'!$E$2:$E$93,4) -> 8007.56
A11: Channel | B11: instagram / social | C11: =SUMIFS('SQL Export'!$G$2:$G$93,'SQL Export'!$C$2:$C$93,$A11,'SQL Export'!$D$2:$D$93,$B11,'SQL Export'!$E$2:$E$93,1) -> 142 | D11: =SUMIFS('SQL Export'!$G$2:$G$93,'SQL Export'!$C$2:$C$93,$A11,'SQL Export'!$D$2:$D$93,$B11,'SQL Export'!$E$2:$E$93,2) -> 44 | E11: =SUMIFS('SQL Export'!$G$2:$G$93,'SQL Export'!$C$2:$C$93,$A11,'SQL Export'!$D$2:$D$93,$B11,'SQL Export'!$E$2:$E$93,3) -> 24 | F11: =SUMIFS('SQL Export'!$G$2:$G$93,'SQL Export'!$C$2:$C$93,$A11,'SQL Export'!$D$2:$D$93,$B11,'SQL Export'!$E$2:$E$93,4) -> 14 | G11: =IFERROR(F11/C11,0) -> 0.098591549 | H11: =SUMIFS('SQL Export'!$M$2:$M$93,'SQL Export'!$C$2:$C$93,$A11,'SQL Export'!$D$2:$D$93,$B11,'SQL Export'!$E$2:$E$93,4) -> 1588.51
A12: Channel | B12: newsletter / email | C12: =SUMIFS('SQL Export'!$G$2:$G$93,'SQL Export'!$C$2:$C$93,$A12,'SQL Export'!$D$2:$D$93,$B12,'SQL Export'!$E$2:$E$93,1) -> 192 | D12: =SUMIFS('SQL Export'!$G$2:$G$93,'SQL Export'!$C$2:$C$93,$A12,'SQL Export'!$D$2:$D$93,$B12,'SQL Export'!$E$2:$E$93,2) -> 100 | E12: =SUMIFS('SQL Export'!$G$2:$G$93,'SQL Export'!$C$2:$C$93,$A12,'SQL Export'!$D$2:$D$93,$B12,'SQL Export'!$E$2:$E$93,3) -> 70 | F12: =SUMIFS('SQL Export'!$G$2:$G$93,'SQL Export'!$C$2:$C$93,$A12,'SQL Export'!$D$2:$D$93,$B12,'SQL Export'!$E$2:$E$93,4) -> 51 | G12: =IFERROR(F12/C12,0) -> 0.265625 | H12: =SUMIFS('SQL Export'!$M$2:$M$93,'SQL Export'!$C$2:$C$93,$A12,'SQL Export'!$D$2:$D$93,$B12,'SQL Export'!$E$2:$E$93,4) -> 5992.56

Sheet Weekly
A2: Weekly Funnel Trend
A3: ISO week is assigned from the session start date in UTC; boundary weeks may be partial.
A4: ISO week | B4: Product views | C4: Add to cart | D4: Begin checkout | E4: Purchases | F4: View-to-purchase rate
A5: 2026-W27 | B5: =SUMIFS('SQL Export'!$G$2:$G$93,'SQL Export'!$C$2:$C$93,"Week",'SQL Export'!$D$2:$D$93,$A5,'SQL Export'!$E$2:$E$93,1) -> 54 | C5: =SUMIFS('SQL Export'!$G$2:$G$93,'SQL Export'!$C$2:$C$93,"Week",'SQL Export'!$D$2:$D$93,$A5,'SQL Export'!$E$2:$E$93,2) -> 21 | D5: =SUMIFS('SQL Export'!$G$2:$G$93,'SQL Export'!$C$2:$C$93,"Week",'SQL Export'!$D$2:$D$93,$A5,'SQL Export'!$E$2:$E$93,3) -> 14 | E5: =SUMIFS('SQL Export'!$G$2:$G$93,'SQL Export'!$C$2:$C$93,"Week",'SQL Export'!$D$2:$D$93,$A5,'SQL Export'!$E$2:$E$93,4) -> 10 | F5: =IFERROR(E5/B5,0) -> 0.18518519
A6: 2026-W28 | B6: =SUMIFS('SQL Export'!$G$2:$G$93,'SQL Export'!$C$2:$C$93,"Week",'SQL Export'!$D$2:$D$93,$A6,'SQL Export'!$E$2:$E$93,1) -> 73 | C6: =SUMIFS('SQL Export'!$G$2:$G$93,'SQL Export'!$C$2:$C$93,"Week",'SQL Export'!$D$2:$D$93,$A6,'SQL Export'!$E$2:$E$93,2) -> 31 | D6: =SUMIFS('SQL Export'!$G$2:$G$93,'SQL Export'!$C$2:$C$93,"Week",'SQL Export'!$D$2:$D$93,$A6,'SQL Export'!$E$2:$E$93,3) -> 17 | E6: =SUMIFS('SQL Export'!$G$2:$G$93,'SQL Export'!$C$2:$C$93,"Week",'SQL Export'!$D$2:$D$93,$A6,'SQL Export'!$E$2:$E$93,4) -> 13 | F6: =IFERROR(E6/B6,0) -> 0.17808219
A7: 2026-W29 | B7: =SUMIFS('SQL Export'!$G$2:$G$93,'SQL Export'!$C$2:$C$93,"Week",'SQL Export'!$D$2:$D$93,$A7,'SQL Export'!$E$2:$E$93,1) -> 77 | C7: =SUMIFS('SQL Export'!$G$2:$G$93,'SQL Export'!$C$2:$C$93,"Week",'SQL Export'!$D$2:$D$93,$A7,'SQL Export'!$E$2:$E$93,2) -> 38 | D7: =SUMIFS('SQL Export'!$G$2:$G$93,'SQL Export'!$C$2:$C$93,"Week",'SQL Export'!$D$2:$D$93,$A7,'SQL Export'!$E$2:$E$93,3) -> 19 | E7: =SUMIFS('SQL Export'!$G$2:$G$93,'SQL Export'!$C$2:$C$93,"Week",'SQL Export'!$D$2:$D$93,$A7,'SQL Export'!$E$2:$E$93,4) -> 15 | F7: =IFERROR(E7/B7,0) -> 0.19480519
A8: 2026-W30 | B8: =SUMIFS('SQL Export'!$G$2:$G$93,'SQL Export'!$C$2:$C$93,"Week",'SQL Export'!$D$2:$D$93,$A8,'SQL Export'!$E$2:$E$93,1) -> 83 | C8: =SUMIFS('SQL Export'!$G$2:$G$93,'SQL Export'!$C$2:$C$93,"Week",'SQL Export'!$D$2:$D$93,$A8,'SQL Export'!$E$2:$E$93,2) -> 33 | D8: =SUMIFS('SQL Export'!$G$2:$G$93,'SQL Export'!$C$2:$C$93,"Week",'SQL Export'!$D$2:$D$93,$A8,'SQL Export'!$E$2:$E$93,3) -> 21 | E8: =SUMIFS('SQL Export'!$G$2:$G$93,'SQL Export'!$C$2:$C$93,"Week",'SQL Export'!$D$2:$D$93,$A8,'SQL Export'!$E$2:$E$93,4) -> 17 | F8: =IFERROR(E8/B8,0) -> 0.20481928
A9: 2026-W31 | B9: =SUMIFS('SQL Export'!$G$2:$G$93,'SQL Export'!$C$2:$C$93,"Week",'SQL Export'!$D$2:$D$93,$A9,'SQL Export'!$E$2:$E$93,1) -> 63 | C9: =SUMIFS('SQL Export'!$G$2:$G$93,'SQL Export'!$C$2:$C$93,"Week",'SQL Export'!$D$2:$D$93,$A9,'SQL Export'!$E$2:$E$93,2) -> 26 | D9: =SUMIFS('SQL Export'!$G$2:$G$93,'SQL Export'!$C$2:$C$93,"Week",'SQL Export'!$D$2:$D$93,$A9,'SQL Export'!$E$2:$E$93,3) -> 15 | E9: =SUMIFS('SQL Export'!$G$2:$G$93,'SQL Export'!$C$2:$C$93,"Week",'SQL Export'!$D$2:$D$93,$A9,'SQL Export'!$E$2:$E$93,4) -> 11 | F9: =IFERROR(E9/B9,0) -> 0.17460317
A10: 2026-W32 | B10: =SUMIFS('SQL Export'!$G$2:$G$93,'SQL Export'!$C$2:$C$93,"Week",'SQL Export'!$D$2:$D$93,$A10,'SQL Export'!$E$2:$E$93,1) -> 73 | C10: =SUMIFS('SQL Export'!$G$2:$G$93,'SQL Export'!$C$2:$C$93,"Week",'SQL Export'!$D$2:$D$93,$A10,'SQL Export'!$E$2:$E$93,2) -> 30 | D10: =SUMIFS('SQL Export'!$G$2:$G$93,'SQL Export'!$C$2:$C$93,"Week",'SQL Export'!$D$2:$D$93,$A10,'SQL Export'!$E$2:$E$93,3) -> 23 | E10: =SUMIFS('SQL Export'!$G$2:$G$93,'SQL Export'!$C$2:$C$93,"Week",'SQL Export'!$D$2:$D$93,$A10,'SQL Export'!$E$2:$E$93,4) -> 14 | F10: =IFERROR(E10/B10,0) -> 0.19178082
A11: 2026-W33 | B11: =SUMIFS('SQL Export'!$G$2:$G$93,'SQL Export'!$C$2:$C$93,"Week",'SQL Export'!$D$2:$D$93,$A11,'SQL Export'!$E$2:$E$93,1) -> 95 | C11: =SUMIFS('SQL Export'!$G$2:$G$93,'SQL Export'!$C$2:$C$93,"Week",'SQL Export'!$D$2:$D$93,$A11,'SQL Export'!$E$2:$E$93,2) -> 37 | D11: =SUMIFS('SQL Export'!$G$2:$G$93,'SQL Export'!$C$2:$C$93,"Week",'SQL Export'!$D$2:$D$93,$A11,'SQL Export'!$E$2:$E$93,3) -> 20 | E11: =SUMIFS('SQL Export'!$G$2:$G$93,'SQL Export'!$C$2:$C$93,"Week",'SQL Export'!$D$2:$D$93,$A11,'SQL Export'!$E$2:$E$93,4) -> 14 | F11: =IFERROR(E11/B11,0) -> 0.14736842
A12: 2026-W34 | B12: =SUMIFS('SQL Export'!$G$2:$G$93,'SQL Export'!$C$2:$C$93,"Week",'SQL Export'!$D$2:$D$93,$A12,'SQL Export'!$E$2:$E$93,1) -> 79 | C12: =SUMIFS('SQL Export'!$G$2:$G$93,'SQL Export'!$C$2:$C$93,"Week",'SQL Export'!$D$2:$D$93,$A12,'SQL Export'!$E$2:$E$93,2) -> 37 | D12: =SUMIFS('SQL Export'!$G$2:$G$93,'SQL Export'!$C$2:$C$93,"Week",'SQL Export'!$D$2:$D$93,$A12,'SQL Export'!$E$2:$E$93,3) -> 24 | E12: =SUMIFS('SQL Export'!$G$2:$G$93,'SQL Export'!$C$2:$C$93,"Week",'SQL Export'!$D$2:$D$93,$A12,'SQL Export'!$E$2:$E$93,4) -> 15 | F12: =IFERROR(E12/B12,0) -> 0.18987342
A13: 2026-W35 | B13: =SUMIFS('SQL Export'!$G$2:$G$93,'SQL Export'!$C$2:$C$93,"Week",'SQL Export'!$D$2:$D$93,$A13,'SQL Export'!$E$2:$E$93,1) -> 86 | C13: =SUMIFS('SQL Export'!$G$2:$G$93,'SQL Export'!$C$2:$C$93,"Week",'SQL Export'!$D$2:$D$93,$A13,'SQL Export'!$E$2:$E$93,2) -> 34 | D13: =SUMIFS('SQL Export'!$G$2:$G$93,'SQL Export'!$C$2:$C$93,"Week",'SQL Export'!$D$2:$D$93,$A13,'SQL Export'!$E$2:$E$93,3) -> 18 | E13: =SUMIFS('SQL Export'!$G$2:$G$93,'SQL Export'!$C$2:$C$93,"Week",'SQL Export'!$D$2:$D$93,$A13,'SQL Export'!$E$2:$E$93,4) -> 12 | F13: =IFERROR(E13/B13,0) -> 0.13953488
A14: 2026-W36 | B14: =SUMIFS('SQL Export'!$G$2:$G$93,'SQL Export'!$C$2:$C$93,"Week",'SQL Export'!$D$2:$D$93,$A14,'SQL Export'!$E$2:$E$93,1) -> 76 | C14: =SUMIFS('SQL Export'!$G$2:$G$93,'SQL Export'!$C$2:$C$93,"Week",'SQL Export'!$D$2:$D$93,$A14,'SQL Export'!$E$2:$E$93,2) -> 38 | D14: =SUMIFS('SQL Export'!$G$2:$G$93,'SQL Export'!$C$2:$C$93,"Week",'SQL Export'!$D$2:$D$93,$A14,'SQL Export'!$E$2:$E$93,3) -> 24 | E14: =SUMIFS('SQL Export'!$G$2:$G$93,'SQL Export'!$C$2:$C$93,"Week",'SQL Export'!$D$2:$D$93,$A14,'SQL Export'!$E$2:$E$93,4) -> 17 | F14: =IFERROR(E14/B14,0) -> 0.22368421
A15: 2026-W37 | B15: =SUMIFS('SQL Export'!$G$2:$G$93,'SQL Export'!$C$2:$C$93,"Week",'SQL Export'!$D$2:$D$93,$A15,'SQL Export'!$E$2:$E$93,1) -> 74 | C15: =SUMIFS('SQL Export'!$G$2:$G$93,'SQL Export'!$C$2:$C$93,"Week",'SQL Export'!$D$2:$D$93,$A15,'SQL Export'!$E$2:$E$93,2) -> 36 | D15: =SUMIFS('SQL Export'!$G$2:$G$93,'SQL Export'!$C$2:$C$93,"Week",'SQL Export'!$D$2:$D$93,$A15,'SQL Export'!$E$2:$E$93,3) -> 22 | E15: =SUMIFS('SQL Export'!$G$2:$G$93,'SQL Export'!$C$2:$C$93,"Week",'SQL Export'!$D$2:$D$93,$A15,'SQL Export'!$E$2:$E$93,4) -> 15 | F15: =IFERROR(E15/B15,0) -> 0.2027027
A16: 2026-W38 | B16: =SUMIFS('SQL Export'!$G$2:$G$93,'SQL Export'!$C$2:$C$93,"Week",'SQL Export'!$D$2:$D$93,$A16,'SQL Export'!$E$2:$E$93,1) -> 75 | C16: =SUMIFS('SQL Export'!$G$2:$G$93,'SQL Export'!$C$2:$C$93,"Week",'SQL Export'!$D$2:$D$93,$A16,'SQL Export'!$E$2:$E$93,2) -> 44 | D16: =SUMIFS('SQL Export'!$G$2:$G$93,'SQL Export'!$C$2:$C$93,"Week",'SQL Export'!$D$2:$D$93,$A16,'SQL Export'!$E$2:$E$93,3) -> 28 | E16: =SUMIFS('SQL Export'!$G$2:$G$93,'SQL Export'!$C$2:$C$93,"Week",'SQL Export'!$D$2:$D$93,$A16,'SQL Export'!$E$2:$E$93,4) -> 18 | F16: =IFERROR(E16/B16,0) -> 0.24
... A18: 2026-W40 | B18: =SUMIFS('SQL Export'!$G$2:$G$93,'SQL Export'!$C$2:$C$93,"Week",'SQL Export'!$D$2:$D$93,$A18,'SQL Export'!$E$2:$E$93,1) -> 18 | C18: =SUMIFS('SQL Export'!$G$2:$G$93,'SQL Export'!$C$2:$C$93,"Week",'SQL Export'!$D$2:$D$93,$A18,'SQL Export'!$E$2:$E$93,2) -> 4 | D18: =SUMIFS('SQL Export'!$G$2:$G$93,'SQL Export'!$C$2:$C$93,"Week",'SQL Export'!$D$2:$D$93,$A18,'SQL Export'!$E$2:$E$93,3) -> 2 | E18: =SUMIFS('SQL Export'!$G$2:$G$93,'SQL Export'!$C$2:$C$93,"Week",'SQL Export'!$D$2:$D$93,$A18,'SQL Export'!$E$2:$E$93,4) -> 0 | F18: =IFERROR(E18/B18,0) -> 0

Sheet SQL Export
A1: report_start_date | B1: report_end_date | C1: view_name | D1: dimension_value | E1: step_order | F1: step_name | G1: step_sessions | H1: previous_step_sessions | I1: conversion_from_previous | J1: dropoff_from_previous | K1: view_entry_sessions | L1: overall_conversion_from_view | M1: purchase_revenue_usd
A2: 46204 | B2: 46293 | C2: Overall | D2: All sessions | E2: 1 | F2: Product view | G2: 1000 | K2: 1000 | L2: 1
A3: 46204 | B3: 46293 | C3: Overall | D3: All sessions | E3: 2 | F3: Add to cart | G3: 443 | H3: 1000 | I3: 0.443 | J3: 0.557 | K3: 1000 | L3: 0.443
A4: 46204 | B4: 46293 | C4: Overall | D4: All sessions | E4: 3 | F4: Begin checkout | G4: 263 | H4: 443 | I4: 0.59367946 | J4: 0.40632054 | K4: 1000 | L4: 0.263
A5: 46204 | B5: 46293 | C5: Overall | D5: All sessions | E5: 4 | F5: Purchase | G5: 183 | H5: 263 | I5: 0.69581749 | J5: 0.30418251 | K5: 1000 | L5: 0.183 | M5: 20982.96
A6: 46204 | B6: 46293 | C6: Device | D6: mobile | E6: 1 | F6: Product view | G6: 650 | K6: 650 | L6: 1
A7: 46204 | B7: 46293 | C7: Device | D7: mobile | E7: 2 | F7: Add to cart | G7: 272 | H7: 650 | I7: 0.41846154 | J7: 0.58153846 | K7: 650 | L7: 0.41846154
A8: 46204 | B8: 46293 | C8: Device | D8: mobile | E8: 3 | F8: Begin checkout | G8: 147 | H8: 272 | I8: 0.54044118 | J8: 0.45955882 | K8: 650 | L8: 0.22615385
A9: 46204 | B9: 46293 | C9: Device | D9: mobile | E9: 4 | F9: Purchase | G9: 95 | H9: 147 | I9: 0.6462585 | J9: 0.3537415 | K9: 650 | L9: 0.14615385 | M9: 10793.08
A10: 46204 | B10: 46293 | C10: Device | D10: desktop | E10: 1 | F10: Product view | G10: 294 | K10: 294 | L10: 1
A11: 46204 | B11: 46293 | C11: Device | D11: desktop | E11: 2 | F11: Add to cart | G11: 145 | H11: 294 | I11: 0.49319728 | J11: 0.50680272 | K11: 294 | L11: 0.49319728
A12: 46204 | B12: 46293 | C12: Device | D12: desktop | E12: 3 | F12: Begin checkout | G12: 99 | H12: 145 | I12: 0.68275862 | J12: 0.31724138 | K12: 294 | L12: 0.33673469
A13: 46204 | B13: 46293 | C13: Device | D13: desktop | E13: 4 | F13: Purchase | G13: 77 | H13: 99 | I13: 0.77777778 | J13: 0.22222222 | K13: 294 | L13: 0.26190476 | M13: 9114.17
A14: 46204 | B14: 46293 | C14: Device | D14: tablet | E14: 1 | F14: Product view | G14: 56 | K14: 56 | L14: 1
A15: 46204 | B15: 46293 | C15: Device | D15: tablet | E15: 2 | F15: Add to cart | G15: 26 | H15: 56 | I15: 0.46428571 | J15: 0.53571429 | K15: 56 | L15: 0.46428571
A16: 46204 | B16: 46293 | C16: Device | D16: tablet | E16: 3 | F16: Begin checkout | G16: 17 | H16: 26 | I16: 0.65384615 | J16: 0.34615385 | K16: 56 | L16: 0.30357143
A17: 46204 | B17: 46293 | C17: Device | D17: tablet | E17: 4 | F17: Purchase | G17: 11 | H17: 17 | I17: 0.64705882 | J17: 0.35294118 | K17: 56 | L17: 0.19642857 | M17: 1075.71
A18: 46204 | B18: 46293 | C18: Channel | D18: google / cpc | E18: 1 | F18: Product view | G18: 239 | K18: 239 | L18: 1
A19: 46204 | B19: 46293 | C19: Channel | D19: google / cpc | E19: 2 | F19: Add to cart | G19: 100 | H19: 239 | I19: 0.41841004 | J19: 0.58158996 | K19: 239 | L19: 0.41841004
A20: 46204 | B20: 46293 | C20: Channel | D20: google / cpc | E20: 3 | F20: Begin checkout | G20: 50 | H20: 100 | I20: 0.5 | J20: 0.5 | K20: 239 | L20: 0.20920502
A21: 46204 | B21: 46293 | C21: Channel | D21: google / cpc | E21: 4 | F21: Purchase | G21: 33 | H21: 50 | I21: 0.66 | J21: 0.34 | K21: 239 | L21: 0.13807531 | M21: 3592.29
A22: 46204 | B22: 46293 | C22: Channel | D22: direct / (none) | E22: 1 | F22: Product view | G22: 79 | K22: 79 | L22: 1
A23: 46204 | B23: 46293 | C23: Channel | D23: direct / (none) | E23: 2 | F23: Add to cart | G23: 35 | H23: 79 | I23: 0.44303797 | J23: 0.55696203 | K23: 79 | L23: 0.44303797
A24: 46204 | B24: 46293 | C24: Channel | D24: direct / (none) | E24: 3 | F24: Begin checkout | G24: 19 | H24: 35 | I24: 0.54285714 | J24: 0.45714286 | K24: 79 | L24: 0.24050633
A25: 46204 | B25: 46293 | C25: Channel | D25: direct / (none) | E25: 4 | F25: Purchase | G25: 16 | H25: 19 | I25: 0.84210526 | J25: 0.15789474 | K25: 79 | L25: 0.20253165 | M25: 1802.04
A26: 46204 | B26: 46293 | C26: Channel | D26: google / organic | E26: 1 | F26: Product view | G26: 348 | K26: 348 | L26: 1
A27: 46204 | B27: 46293 | C27: Channel | D27: google / organic | E27: 2 | F27: Add to cart | G27: 164 | H27: 348 | I27: 0.47126437 | J27: 0.52873563 | K27: 348 | L27: 0.47126437
A28: 46204 | B28: 46293 | C28: Channel | D28: google / organic | E28: 3 | F28: Begin checkout | G28: 100 | H28: 164 | I28: 0.6097561 | J28: 0.3902439 | K28: 348 | L28: 0.28735632
A29: 46204 | B29: 46293 | C29: Channel | D29: google / organic | E29: 4 | F29: Purchase | G29: 69 | H29: 100 | I29: 0.69 | J29: 0.31 | K29: 348 | L29: 0.19827586 | M29: 8007.56
A30: 46204 | B30: 46293 | C30: Channel | D30: newsletter / email | E30: 1 | F30: Product view | G30: 192 | K30: 192 | L30: 1
A31: 46204 | B31: 46293 | C31: Channel | D31: newsletter / email | E31: 2 | F31: Add to cart | G31: 100 | H31: 192 | I31: 0.52083333 | J31: 0.47916667 | K31: 192 | L31: 0.52083333
A32: 46204 | B32: 46293 | C32: Channel | D32: newsletter / email | E32: 3 | F32: Begin checkout | G32: 70 | H32: 100 | I32: 0.7 | J32: 0.3 | K32: 192 | L32: 0.36458333
A33: 46204 | B33: 46293 | C33: Channel | D33: newsletter / email | E33: 4 | F33: Purchase | G33: 51 | H33: 70 | I33: 0.72857143 | J33: 0.27142857 | K33: 192 | L33: 0.265625 | M33: 5992.56
A34: 46204 | B34: 46293 | C34: Channel | D34: instagram / social | E34: 1 | F34: Product view | G34: 142 | K34: 142 | L34: 1
A35: 46204 | B35: 46293 | C35: Channel | D35: instagram / social | E35: 2 | F35: Add to cart | G35: 44 | H35: 142 | I35: 0.30985915 | J35: 0.69014085 | K35: 142 | L35: 0.30985915
A36: 46204 | B36: 46293 | C36: Channel | D36: instagram / social | E36: 3 | F36: Begin checkout | G36: 24 | H36: 44 | I36: 0.54545455 | J36: 0.45454545 | K36: 142 | L36: 0.16901408
A37: 46204 | B37: 46293 | C37: Channel | D37: instagram / social | E37: 4 | F37: Purchase | G37: 14 | H37: 24 | I37: 0.58333333 | J37: 0.41666667 | K37: 142 | L37: 0.098591549 | M37: 1588.51
A38: 46204 | B38: 46293 | C38: Week | D38: 2026-W27 | E38: 1 | F38: Product view | G38: 54 | K38: 54 | L38: 1
A39: 46204 | B39: 46293 | C39: Week | D39: 2026-W27 | E39: 2 | F39: Add to cart | G39: 21 | H39: 54 | I39: 0.38888889 | J39: 0.61111111 | K39: 54 | L39: 0.38888889
A40: 46204 | B40: 46293 | C40: Week | D40: 2026-W27 | E40: 3 | F40: Begin checkout | G40: 14 | H40: 21 | I40: 0.66666667 | J40: 0.33333333 | K40: 54 | L40: 0.25925926
...
